Workbook

Sheet Instructions
A1: Sentinel Firewall local adaptation workbook
A3: Purpose | B3: This workbook accompanies the paper 'The Sentinel Firewall: A Health-System Strategy to Decouple Informal Industrialization from Lead Exposure in LMICs.' The paper asks whether maternal and child health platforms can temporarily reduce lead exposure by replacing contaminated household products with safe substitutes while regulation catches up. This spreadsheet is a simplified local-decision version of that model.
A5: What this tool does | B5: It compares two packages: a Kitchen Package (safe pot, calcium, child utensils) and a Kohl Package (safe maternal and infant kohl). It converts programme delivery into lower maternal and child blood lead levels, child IQ gains, lifetime earnings gains, maternal and neonatal health gains, and secondary adult cardiovascular gains.
A7: Who should use it | B7: This workbook is designed for Ministries of Health, NGOs, environmental health programmes, and local researchers who want to ask a practical question: if local prices, prevalence, attendance, and implementation quality look like our setting, would targeted safe-product substitution likely be worth funding?
A9: How to use it | B9: Go to the Inputs sheet. The grey Default column contains the author's modal assumptions and is locked. Enter local values only in the yellow 'Your local value' column. The green 'Active value' column will automatically use your entry when present and otherwise fall back to the default. The Topline sheet then compares the workbook-default mode-only results with your local mode-only scenario.
A11: What to change first | B11: Start with parameters local decision-makers are most likely to know or influence: GDP per capita, labour share, mortality, product prices, district births and overhead, prevalence in the targeted area, attendance, voucher redemption, stock, and adherence. Scientific parameters such as BLL-to-IQ and IQ-to-earnings are grouped separately and marked 'change cautiously'.
A13: How productivity is defined | B13: Productivity is measured as GDP per capita at purchasing power parity multiplied by labour's share of national income. This values market labour output, including self-employment and informal production that would be missed by observed wages alone. It excludes household production and the intrinsic value of cognition beyond earnings, so the earnings channel remains conservative on that dimension.
A15: Important limitation | B15: This is a deterministic mode-only tool. It does not run the 10,000-draw Monte Carlo uncertainty analysis, does not model parameter correlations, and does not export trial-level data. Use the public Python model for the full probabilistic sensitivity analysis and publication-quality figures.
A17: Public files | B17: Public copies are posted in the Sentinel-Firewall GitHub repository at https://github.com/levine63/Sentinel-Firewall. The main public files are submission_package/public_code_and_data/sentinel_firewall_model.py and submission_package/public_code_and_data/Simulating_sentinel_safe_products.xlsx.

Sheet Inputs
A1: Parameter group | B1: Parameter | C1: Units | D1: Default modal value (locked) | E1: Your local value (edit here) | F1: Active value | G1: Low | H1: High | I1: Why it matters / plain-language description | J1: Citation basis | K1: Change guidance | L1: Internal name
A2: Local macro and demography
A3: Local macro and demography | B3: GDP per capita, PPP | C3: US$ per person per year | D3: 4000 | F3: =IF(LEN(E3)=0,D3,E3) | G3: 2000 | H3: 8000 | I3: Represents a conservative LMIC district-level range rather than an all-country global mean. | J3: World Bank, GDP per capita, PPP (current international $), lower-middle-income and country comparator series. [World Bank](https://data.worldbank.org/indicator/NY.GDP.PCAP.PP.CD?locations=XN) | K3: Usually known locally or from public statistics | L3: gdp_ppp_per_capita
A4: Local macro and demography | B4: Labour share of national income | C4: Share of GDP | D4: 0.55 | F4: =IF(LEN(E4)=0,D4,E4) | G4: 0.5 | H4: 0.58 | I4: Labour share of national income, used to convert PPP GDP per capita into an annual market-labour productivity anchor. This replaces labour-force participation because GDP per capita already averages across the population; multiplying by labour's share captures labour output including self-employment and informal market production while avoiding reliance on observed wage rates alone. | J4: ILO labour income share context; Gollin's correction for self-employment and mixed income; World Bank human-capital valuation logic. [ILO WESO](https://www.ilo.org/publications/flagship-reports/world-employment-and-social-outlook-trends-2025), [Gollin](https://ideas.repec.org/a/ucp/jpolec/v110y2002i2p458-474.html), [World Bank CWON](https://www.worldbank.org/en/publication/changing-wealth-of-nations) | K4: Usually known from public macro data or left at default | L4: labor_share_income
A5: Local macro and demography | B5: Real annual productivity growth | C5: Annual rate | D5: 0.02 | F5: =IF(LEN(E5)=0,D5,E5) | G5: 0 | H5: 0.025 | I5: Conservative long-run productivity growth assumption for LMIC decision analysis. | J5: Program-design assumption anchored in World Bank and ILO growth context; not taken from a single causal paper. | K5: Change if you have a strong local reason | L5: growth
A6: Local macro and demography | B6: Social discount rate | C6: Annual rate | D6: 0.03 | F6: =IF(LEN(E6)=0,D6,E6) | G6: 0.01 | H6: 0.05 | I6: Standard health-economic social discount range. | J6: Briggs, Claxton, and Sculpher (2006). | K6: Policy/evaluation choice | L6: discount
A7: Local macro and demography | B7: Survival from birth to age 18 | C7: Probability | D7: 0.95 | F7: =IF(LEN(E7)=0,D7,E7) | G7: 0.92 | H7: 0.97 | I7: Reflects survival to adulthood in contemporary LMIC settings. | J7: UN child mortality context and World Bank life-table indicators. UNICEF/UN IGME child mortality; World Bank survival indicators. [UNICEF](https://data.unicef.org/topic/child-survival/under-five-mortality/) | K7: Usually known locally or from public statistics | L7: p18
A8: Local macro and demography | B8: Survival from birth to age 65 | C8: Probability | D8: 0.78 | F8: =IF(LEN(E8)=0,D8,E8) | G8: 0.68 | H8: 0.85 | I8: Captures plausible unconditional survival to age 65 across higher- and lower-survival LMIC settings. | J8: World Bank survival to age 65 indicator. [World Bank](https://genderdata.worldbank.org/en/indicator/sp-dyn-to65-zs) | K8: Usually known locally or from public statistics | L8: p65
A9: Local macro and demography | B9: Mortality timing shape parameter | C9: Unitless | D9: 2 | F9: =IF(LEN(E9)=0,D9,E9) | G9: 1.5 | H9: 3 | I9: Shape parameter used to concentrate mortality later in the working life. | J9: Structural modeling assumption; no direct empirical source. | K9: Usually leave at default | L9: k
A10: Local macro and demography | B10: Age when earnings begin | C10: Years | D10: 18 | F10: =IF(LEN(E10)=0,D10,E10) | G10: 14 | H10: 20 | I10: Captures informal labor entry at the low end and delayed formal entry at the high end. | J10: ILO child labor and youth labor-force context; program-design range. | K10: Usually known locally | L10: labor_entry_age
A11: Local macro and demography | B11: Mother age at intervention | C11: Years | D11: 25 | F11: =IF(LEN(E11)=0,D11,E11) | G11: 18 | H11: 35 | I11: Plausible age range for mothers reached by ANC in LMIC settings. | J11: DHS fertility and maternal age distributions; program-design range. | K11: Usually known locally | L11: mom_age
A12: Local macro and demography | B12: Grandparent age at intervention | C12: Years | D12: 52 | F12: =IF(LEN(E12)=0,D12,E12) | G12: 42 | H12: 70 | I12: Representative intergenerational age span for co-resident grandparents. | J12: Household-structure and fertility-timing synthesis; program-design range. | K12: Usually leave at default | L12: gp_age
A13: Local macro and demography | B13: Grandparent co-residence | C13: Probability | D13: 0.5 | F13: =IF(LEN(E13)=0,D13,E13) | G13: 0.2 | H13: 0.7 | I13: Captures substantial cross-setting variation in multigenerational co-residence. | J13: DHS and household structure synthesis; program-design range. | K13: Usually known locally | L13: gp_coresidence_prob
A14: Prices and overhead
A15: Prices and overhead | B15: Lead-safe pot product cost | C15: US$ | D15: 12 | F15: =IF(LEN(E15)=0,D15,E15) | G15: 8 | H15: 15 | I15: Direct cost of safe pot before logistics and overhead. | J15: Program-budget assumption informed by procurement and retail comparators; requires local validation before implementation. | K15: Good local input | L15: cost_pot_direct
A16: Prices and overhead | B16: Safe child feeding-utensil product cost | C16: US$ | D16: 1.5 | F16: =IF(LEN(E16)=0,D16,E16) | G16: 1 | H16: 2.5 | I16: Direct cost of utensils or cup-spoon substitute. | J16: Program-budget assumption informed by low-cost commodity procurement comparators. | K16: Good local input | L16: cost_utensils_direct
A17: Prices and overhead | B17: Calcium course product cost | C17: US$ | D17: 1.75 | F17: =IF(LEN(E17)=0,D17,E17) | G17: 1.25 | H17: 3 | I17: Direct cost of calcium course. | J17: WHO calcium guideline context and UNICEF supply-style commodity pricing. [WHO](https://www.who.int/publications/i/item/9789241505376) | K17: Good local input | L17: cost_calcium_direct
A18: Prices and overhead | B18: Safe maternal kohl product cost | C18: US$ | D18: 0.75 | F18: =IF(LEN(E18)=0,D18,E18) | G18: 0.4 | H18: 1.25 | I18: Direct cost of safe maternal kohl substitute. | J18: Program-budget assumption informed by low-cost cosmetic substitution framing; local market validation needed. | K18: Good local input | L18: cost_kohl_maternal_direct
A19: Prices and overhead | B19: Safe infant kohl product cost | C19: US$ | D19: 1.5 | F19: =IF(LEN(E19)=0,D19,E19) | G19: 1.2 | H19: 3 | I19: Direct cost of infant kohl substitute. | J19: Program-budget assumption; local procurement validation needed. | K19: Good local input | L19: cost_kohl_infant_direct
A20: Prices and overhead | B20: Counseling and explanation cost per contact | C20: US$ | D20: 0.35 | F20: =IF(LEN(E20)=0,D20,E20) | G20: 0.3 | H20: 0.5 | I20: Counseling and explanation cost per relevant contact. | J20: Health worker time-cost assumption informed by WHO costing conventions and low-wage program delivery settings. | K20: Programme lever | L20: cost_explain
A21: Prices and overhead | B21: Bulk distribution plus retailer margin for pot | C21: US$ | D21: 4 | F21: =IF(LEN(E21)=0,D21,E21) | G21: 3 | H21: 5 | I21: Bulk distribution cost plus retailer margin for pot voucher redemption. The previous bulk distribution line is increased by approximately `2` to include merchant compensation explicitly. | J21: Program-logistics and retailer-margin assumption. | K21: Programme lever | L21: cost_bulk_distribution_margin
A22: Prices and overhead | B22: Distribution cost for small item | C22: US$ | D22: 0.5 | F22: =IF(LEN(E22)=0,D22,E22) | G22: 0.25 | H22: 1 | I22: Distribution cost for smaller goods. | J22: Program-logistics assumption. | K22: Programme lever | L22: cost_dist_light
A23: Prices and overhead | B23: Programme overhead markup | C23: Share of direct product plus distribution cost | D23: 0.6 | F23: =IF(LEN(E23)=0,D23,E23) | G23: 0.3 | H23: 1 | I23: Program markup applied to direct product plus distribution costs. Because retailer margin is now included in the bulk pot distribution line, this parameter covers wastage, supply-chain overhead, shrinkage, supervision, and health-system administration. | J23: Program-budget assumption informed by public-health supply-chain and administration experience. | K23: Programme lever | L23: logistics_markup
A24: Prices and overhead | B24: National and district fixed programme cost per screening unit | C24: US$ | D24: 50000 | F24: =IF(LEN(E24)=0,D24,E24) | G24: 20000 | H24: 100000 | I24: Fully loaded national and district-level sentinel screening and program setup cost. | J24: Program-design assumption informed by XRF procurement, supervision, training, coordination, and district operations needs. | K24: Good local input | L24: district_fixed_cost
A25: Prices and overhead | B25: Births per screening unit | C25: Births | D25: 20000 | F25: =IF(LEN(E25)=0,D25,E25) | G25: 4000 | H25: 50000 | I25: Effective births per screening unit for spreading overhead. The mode assumes a shared-service model in which XRF assets and specialized supervision are used across multiple smaller districts or catchments. | J25: Administrative and fertility-design assumption anchored in DHS birth rates, district heterogeneity, and capital-efficiency logic. | K25: Good local input | L25: district_births
A26: Targeting and prevalence
A27: Targeting and prevalence | B27: Unsafe pot prevalence in targeted households | C27: Share | D27: 0.75 | F27: =IF(LEN(E27)=0,D27,E27) | G27: 0.5 | H27: 0.9 | I27: Hazard prevalence among households in screened red districts. The range assumes sentinel screening can target somewhat better than a broad district average. | J27: Pure Earth and hotspot screening logic; synthesis assumption requiring local validation. | K27: Good local input | L27: prev_pot
A28: Targeting and prevalence | B28: Unsafe maternal kohl prevalence in targeted households | C28: Share | D28: 0.7 | F28: =IF(LEN(E28)=0,D28,E28) | G28: 0.4 | H28: 0.85 | I28: Maternal kohl prevalence in higher-use settings selected for intervention. The higher mode reflects that this is a conditional prevalence in screened hotspots rather than a national average. | J28: Survey, ethnographic, and clinical synthesis of traditional eye cosmetic use; see kohl citations below. The parameter is partly endogenous to programme management because stricter hotspot screening and higher intervention thresholds will raise prevalence among those targeted. | K28: Good local input | L28: prev_kohl_maternal
A29: Targeting and prevalence | B29: Unsafe infant kohl prevalence in targeted households | C29: Share | D29: 0.7 | F29: =IF(LEN(E29)=0,D29,E29) | G29: 0.4 | H29: 0.85 | I29: Infant kohl prevalence among infants in high-use settings. The main model allows exposure among boys as well as girls; a separate robustness check restricts infant kohl substitution to girls only. | J29: Survey and ethnographic synthesis; see kohl citations below. The higher mode reflects settings where infant kohl use is common across both sexes and where screening is intended to select strongly affected areas rather than marginal districts. | K29: Good local input | L29: prev_kohl_infant
A30: Targeting and prevalence | B30: Unsafe child feeding-utensil prevalence in targeted households | C30: Share | D30: 0.6 | F30: =IF(LEN(E30)=0,D30,E30) | G30: 0.4 | H30: 0.8 | I30: Unsafe utensil prevalence in targeted hotspots. | J30: Program-design assumption informed by lead-glazed ceramic exposure literature and sentinel targeting logic. | K30: Good local input | L30: prev_utensils
A31: Implementation and programme reach
A32: Implementation and programme reach | B32: Attendance at antenatal care contact | C32: Probability | D32: 0.82 | F32: =IF(LEN(E32)=0,D32,E32) | G32: 0.55 | H32: 0.95 | I32: ANC-1 attendance benchmark. | J32: UNICEF antenatal care data. [UNICEF](https://data.unicef.org/topic/maternal-health/antenatal-care/) | K32: Good local input | L32: p_att_anc
A33: Implementation and programme reach | B33: Attendance at 6-month immunization contact | C33: Probability | D33: 0.8 | F33: =IF(LEN(E33)=0,D33,E33) | G33: 0.5 | H33: 0.95 | I33: Reflects DTP3-style immunization platform reach in many LMIC settings. | J33: UNICEF immunization statistics. [UNICEF](https://data.unicef.org/topic/child-health/immunization/) | K33: Good local input | L33: p_att_imm
A34: Implementation and programme reach | B34: Institutional delivery contact | C34: Probability | D34: 0.65 | F34: =IF(LEN(E34)=0,D34,E34) | G34: 0.4 | H34: 0.85 | I34: Institutional delivery range retained as a reference contact parameter. Infant kohl now uses the combined facility-delivery-or-early-immunization contact below. | J34: UNICEF and DHS-style institutional delivery coverage context; program-design range. | K34: Good local input | L34: p_att_birth
A35: Implementation and programme reach | B35: Infant kohl contact through facility delivery or early immunization | C35: Probability | D35: 0.8 | F35: =IF(LEN(E35)=0,D35,E35) | G35: 0.55 | H35: 0.95 | I35: Combined probability that an infant can be reached for safe kohl through either facility delivery or early immunization catch-up. The mode is a union of correlated contacts, not the sum of independent delivery and immunization probabilities. | J35: UNICEF institutional delivery and immunization coverage benchmarks; program-design assumption requiring local validation. [UNICEF delivery](https://data.unicef.org/topic/maternal-health/delivery-care/), [UNICEF immunization](https://data.unicef.org/topic/child-health/immunization/) | K35: Good local input | L35: p_att_infant_kohl_contact
A36: Implementation and programme reach | B36: Health-system delivery fidelity | C36: Probability | D36: 0.6 | F36: =IF(LEN(E36)=0,D36,E36) | G36: 0.3 | H36: 0.8 | I36: Generic delivery fidelity for clinic-distributed components. | J36: Essential medicines availability literature and implementation synthesis; broader LMIC availability reviews. [PubMed](https://pubmed.ncbi.nlm.nih.gov/37340382/) | K36: Programme lever | L36: fidelity
A37: Implementation and programme reach | B37: Complete substitution or adherence | C37: Probability | D37: 0.5 | F37: =IF(LEN(E37)=0,D37,E37) | G37: 0.3 | H37: 0.6 | I37: Complete use or substitution rate after receipt for non-pot components. | J37: Behavioral and implementation synthesis; program-design range. | K37: Programme lever | L37: adherence
A38: Implementation and programme reach | B38: Pot voucher issued at ANC | C38: Probability | D38: 0.7 | F38: =IF(LEN(E38)=0,D38,E38) | G38: 0.4 | H38: 0.9 | I38: Probability eligible ANC attendee actually receives pot voucher. | J38: Voucher-program implementation assumption informed by health subsidy distribution literature. | K38: Programme lever | L38: p_voucher_issued
A39: Implementation and programme reach | B39: Approved merchant has safe pot in stock | C39: Probability | D39: 0.8 | F39: =IF(LEN(E39)=0,D39,E39) | G39: 0.6 | H39: 0.95 | I39: Probability approved merchant has stock when voucher holder presents. The higher values reflect active contracting with approved retailers rather than passive clinic stock alone. | J39: Supply chain and medicines availability literature; implementation assumption. | K39: Programme lever | L39: p_merchant_stock
A40: Implementation and programme reach | B40: Pot voucher redeemed | C40: Probability | D40: 0.75 | F40: =IF(LEN(E40)=0,D40,E40) | G40: 0.6 | H40: 0.9 | I40: Voucher redemption for a high-value durable household product. | J40: Dupas et al. (2016) and related subsidy redemption evidence; values are higher than low-value preventive products because pots are useful durable goods. [PubMed](https://pubmed.ncbi.nlm.nih.gov/27563091/) | K40: Programme lever | L40: p_redeem
...

Sheet Formula_Guide
A1: Concept | B1: Plain-language meaning | C1: Formula used in this workbook | D1: Notes
A2: Present value of lifetime earnings | B2: Expected discounted lifetime earnings from birth. | C2: Productivity x growth/discount adjustment from birth to labour entry x sum of working-year survival and growth/discount terms. | D2: Productivity is GDP PPP per capita x labour share of national income.
A3: Productivity | B3: Annual market-labour output used to value lifetime earnings and VSLY. | C3: GDP per capita, PPP x labour share of national income. | D3: This follows social cost-benefit practice and includes self-employment and informal market production better than observed wages alone.
A4: Pot implementation chain | B4: The safe pot only generates benefit when the household is correctly targeted, reaches ANC, receives a voucher, finds a stocked merchant, redeems the voucher, and uses the pot for the pregnant woman or young child. | C4: Unsafe-pot prevalence x ANC attendance x voucher issued x merchant stocked x voucher redeemed x targeted use x (1 - residual unsafe-use harm). | D4: Costs for the pot are incurred only after attendance, voucher issuance, merchant stock, and redemption; fixed overhead remains regardless.
A5: Clinic-distributed items | B5: Calcium, child utensils, maternal kohl, and infant kohl use shorter delivery chains. | C5: Relevant prevalence where applicable x relevant health-system contact x fidelity x adherence. | D5: Calcium currently helps all reached pregnant women in the targeted area rather than only women with a measured lead source.
A6: Developmental timing | B6: An intervention that lasts only during part of pregnancy or early childhood does not receive the full cognitive benefit of lowering BLL throughout the developmental window. | C6: Prenatal BLL reduction x prenatal share + postnatal BLL reduction x years-protected share. | D6: The default shares are 30% for the last four months in utero, 30% for year 1, and 40% for years 2-5 combined.
A7: IQ gain | B7: Lower developmentally weighted child blood lead increases expected IQ. | C7: Developmentally weighted child BLL reduction x IQ gain per 1 ug/dL lower BLL. | D7: The full Python model also reports a nonlinear log-BLL robustness check.
A8: Lifetime earnings gain | B8: IQ gains raise expected lifetime earnings. | C8: Present value of lifetime earnings x earnings gain per IQ point x IQ gain. | D8: This is the main cognition-channel social benefit.
A9: Benefit-cost ratio | B9: Social benefits divided by programme costs. | C9: Benefits / costs. | D9: The Topline sheet compares the workbook-default mode-only run with your local mode-only run for cognition-only, maternal/neonatal, and total BCRs.

Sheet PV_Helper
A1: Working year | B1: Survival S_t (default) | C1: Survival S_t (local) | D1: Growth-discount factor (default) | E1: Growth-discount factor (local) | F1: Included in work life (default) | G1: Included in work life (local) | H1: PV term (default) | I1: PV term (local)
A2: 1 | B2: =Inputs!$D$7-(Inputs!$D$7-Inputs!$D$8)*POWER((A2-1)/47,Inputs!$D$9) | C2: =Inputs!$F$7-(Inputs!$F$7-Inputs!$F$8)*POWER((A2-1)/47,Inputs!$F$9) | D2: =POWER(((1+Inputs!$D$5)/(1+Inputs!$D$6)),A2-1) | E2: =POWER(((1+Inputs!$F$5)/(1+Inputs!$F$6)),A2-1) | F2: =--(A2<=(65-Inputs!$D$10+1)) | G2: =--(A2<=(65-Inputs!$F$10+1)) | H2: =B2*D2*F2 | I2: =C2*E2*G2
A3: 2 | B3: =Inputs!$D$7-(Inputs!$D$7-Inputs!$D$8)*POWER((A3-1)/47,Inputs!$D$9) | C3: =Inputs!$F$7-(Inputs!$F$7-Inputs!$F$8)*POWER((A3-1)/47,Inputs!$F$9) | D3: =POWER(((1+Inputs!$D$5)/(1+Inputs!$D$6)),A3-1) | E3: =POWER(((1+Inputs!$F$5)/(1+Inputs!$F$6)),A3-1) | F3: =--(A3<=(65-Inputs!$D$10+1)) | G3: =--(A3<=(65-Inputs!$F$10+1)) | H3: =B3*D3*F3 | I3: =C3*E3*G3
A4: 3 | B4: =Inputs!$D$7-(Inputs!$D$7-Inputs!$D$8)*POWER((A4-1)/47,Inputs!$D$9) | C4: =Inputs!$F$7-(Inputs!$F$7-Inputs!$F$8)*POWER((A4-1)/47,Inputs!$F$9) | D4: =POWER(((1+Inputs!$D$5)/(1+Inputs!$D$6)),A4-1) | E4: =POWER(((1+Inputs!$F$5)/(1+Inputs!$F$6)),A4-1) | F4: =--(A4<=(65-Inputs!$D$10+1)) | G4: =--(A4<=(65-Inputs!$F$10+1)) | H4: =B4*D4*F4 | I4: =C4*E4*G4
A5: 4 | B5: =Inputs!$D$7-(Inputs!$D$7-Inputs!$D$8)*POWER((A5-1)/47,Inputs!$D$9) | C5: =Inputs!$F$7-(Inputs!$F$7-Inputs!$F$8)*POWER((A5-1)/47,Inputs!$F$9) | D5: =POWER(((1+Inputs!$D$5)/(1+Inputs!$D$6)),A5-1) | E5: =POWER(((1+Inputs!$F$5)/(1+Inputs!$F$6)),A5-1) | F5: =--(A5<=(65-Inputs!$D$10+1)) | G5: =--(A5<=(65-Inputs!$F$10+1)) | H5: =B5*D5*F5 | I5: =C5*E5*G5
A6: 5 | B6: =Inputs!$D$7-(Inputs!$D$7-Inputs!$D$8)*POWER((A6-1)/47,Inputs!$D$9) | C6: =Inputs!$F$7-(Inputs!$F$7-Inputs!$F$8)*POWER((A6-1)/47,Inputs!$F$9) | D6: =POWER(((1+Inputs!$D$5)/(1+Inputs!$D$6)),A6-1) | E6: =POWER(((1+Inputs!$F$5)/(1+Inputs!$F$6)),A6-1) | F6: =--(A6<=(65-Inputs!$D$10+1)) | G6: =--(A6<=(65-Inputs!$F$10+1)) | H6: =B6*D6*F6 | I6: =C6*E6*G6
A7: 6 | B7: =Inputs!$D$7-(Inputs!$D$7-Inputs!$D$8)*POWER((A7-1)/47,Inputs!$D$9) | C7: =Inputs!$F$7-(Inputs!$F$7-Inputs!$F$8)*POWER((A7-1)/47,Inputs!$F$9) | D7: =POWER(((1+Inputs!$D$5)/(1+Inputs!$D$6)),A7-1) | E7: =POWER(((1+Inputs!$F$5)/(1+Inputs!$F$6)),A7-1) | F7: =--(A7<=(65-Inputs!$D$10+1)) | G7: =--(A7<=(65-Inputs!$F$10+1)) | H7: =B7*D7*F7 | I7: =C7*E7*G7
A8: 7 | B8: =Inputs!$D$7-(Inputs!$D$7-Inputs!$D$8)*POWER((A8-1)/47,Inputs!$D$9) | C8: =Inputs!$F$7-(Inputs!$F$7-Inputs!$F$8)*POWER((A8-1)/47,Inputs!$F$9) | D8: =POWER(((1+Inputs!$D$5)/(1+Inputs!$D$6)),A8-1) | E8: =POWER(((1+Inputs!$F$5)/(1+Inputs!$F$6)),A8-1) | F8: =--(A8<=(65-Inputs!$D$10+1)) | G8: =--(A8<=(65-Inputs!$F$10+1)) | H8: =B8*D8*F8 | I8: =C8*E8*G8
A9: 8 | B9: =Inputs!$D$7-(Inputs!$D$7-Inputs!$D$8)*POWER((A9-1)/47,Inputs!$D$9) | C9: =Inputs!$F$7-(Inputs!$F$7-Inputs!$F$8)*POWER((A9-1)/47,Inputs!$F$9) | D9: =POWER(((1+Inputs!$D$5)/(1+Inputs!$D$6)),A9-1) | E9: =POWER(((1+Inputs!$F$5)/(1+Inputs!$F$6)),A9-1) | F9: =--(A9<=(65-Inputs!$D$10+1)) | G9: =--(A9<=(65-Inputs!$F$10+1)) | H9: =B9*D9*F9 | I9: =C9*E9*G9
A10: 9 | B10: =Inputs!$D$7-(Inputs!$D$7-Inputs!$D$8)*POWER((A10-1)/47,Inputs!$D$9) | C10: =Inputs!$F$7-(Inputs!$F$7-Inputs!$F$8)*POWER((A10-1)/47,Inputs!$F$9) | D10: =POWER(((1+Inputs!$D$5)/(1+Inputs!$D$6)),A10-1) | E10: =POWER(((1+Inputs!$F$5)/(1+Inputs!$F$6)),A10-1) | F10: =--(A10<=(65-Inputs!$D$10+1)) | G10: =--(A10<=(65-Inputs!$F$10+1)) | H10: =B10*D10*F10 | I10: =C10*E10*G10
A11: 10 | B11: =Inputs!$D$7-(Inputs!$D$7-Inputs!$D$8)*POWER((A11-1)/47,Inputs!$D$9) | C11: =Inputs!$F$7-(Inputs!$F$7-Inputs!$F$8)*POWER((A11-1)/47,Inputs!$F$9) | D11: =POWER(((1+Inputs!$D$5)/(1+Inputs!$D$6)),A11-1) | E11: =POWER(((1+Inputs!$F$5)/(1+Inputs!$F$6)),A11-1) | F11: =--(A11<=(65-Inputs!$D$10+1)) | G11: =--(A11<=(65-Inputs!$F$10+1)) | H11: =B11*D11*F11 | I11: =C11*E11*G11
A12: 11 | B12: =Inputs!$D$7-(Inputs!$D$7-Inputs!$D$8)*POWER((A12-1)/47,Inputs!$D$9) | C12: =Inputs!$F$7-(Inputs!$F$7-Inputs!$F$8)*POWER((A12-1)/47,Inputs!$F$9) | D12: =POWER(((1+Inputs!$D$5)/(1+Inputs!$D$6)),A12-1) | E12: =POWER(((1+Inputs!$F$5)/(1+Inputs!$F$6)),A12-1) | F12: =--(A12<=(65-Inputs!$D$10+1)) | G12: =--(A12<=(65-Inputs!$F$10+1)) | H12: =B12*D12*F12 | I12: =C12*E12*G12
A13: 12 | B13: =Inputs!$D$7-(Inputs!$D$7-Inputs!$D$8)*POWER((A13-1)/47,Inputs!$D$9) | C13: =Inputs!$F$7-(Inputs!$F$7-Inputs!$F$8)*POWER((A13-1)/47,Inputs!$F$9) | D13: =POWER(((1+Inputs!$D$5)/(1+Inputs!$D$6)),A13-1) | E13: =POWER(((1+Inputs!$F$5)/(1+Inputs!$F$6)),A13-1) | F13: =--(A13<=(65-Inputs!$D$10+1)) | G13: =--(A13<=(65-Inputs!$F$10+1)) | H13: =B13*D13*F13 | I13: =C13*E13*G13
... A53: 52 | B53: =Inputs!$D$7-(Inputs!$D$7-Inputs!$D$8)*POWER((A53-1)/47,Inputs!$D$9) | C53: =Inputs!$F$7-(Inputs!$F$7-Inputs!$F$8)*POWER((A53-1)/47,Inputs!$F$9) | D53: =POWER(((1+Inputs!$D$5)/(1+Inputs!$D$6)),A53-1) | E53: =POWER(((1+Inputs!$F$5)/(1+Inputs!$F$6)),A53-1) | F53: =--(A53<=(65-Inputs!$D$10+1)) | G53: =--(A53<=(65-Inputs!$F$10+1)) | H53: =B53*D53*F53 | I53: =C53*E53*G53

Sheet Results
A1: Detailed deterministic calculations (advanced users)
A2: Metric | B2: Workbook default | C2: Your local run | D2: Notes and units
A3: Annual productivity anchor | B3: =Inputs!$D$3*Inputs!$D$4 | C3: =Inputs!$F$3*Inputs!$F$4 | D3: US$ per person-year. GDP PPP per capita x labour share of national income.
A4: Growth-discount ratio (x) | B4: =((1+Inputs!$D$5)/(1+Inputs!$D$6)) | C4: =((1+Inputs!$F$5)/(1+Inputs!$F$6)) | D4: Unitless ratio = (1+growth)/(1+discount).
A5: Present value of lifetime earnings | B5: =B3*POWER(B4,Inputs!$D$10)*SUM(PV_Helper!H2:H53) | C5: =C3*POWER(C4,Inputs!$F$10)*SUM(PV_Helper!I2:I53) | D5: US$ per child from birth.
A6: Fixed programme cost per mother-child pair | B6: =Inputs!$D$24/Inputs!$D$25 | C6: =Inputs!$F$24/Inputs!$F$25 | D6: US$. Includes national and district fixed costs spread over births in the screening unit.
A7: Value assigned to one DALY / life-year equivalent | B7: =Inputs!$D$65*B3 | C7: =Inputs!$F$65*C3 | D7: US$. Used only in the health-inclusive calculations.
A8: Developmental share assigned to ages 2 to 5 | B8: =1-Inputs!$D$54-Inputs!$D$55 | C8: =1-Inputs!$F$54-Inputs!$F$55 | D8: Share of total cognition-relevant exposure window.
A9: Postnatal developmental weight applied to pot pathway | B9: =Inputs!$D$55*MIN(Inputs!$D$68,1)+B8*(MIN(MAX(Inputs!$D$68-1,0),4)/4) | C9: =Inputs!$F$55*MIN(Inputs!$F$68,1)+C8*(MIN(MAX(Inputs!$F$68-1,0),4)/4) | D9: Share of cognition-relevant window reached by the pot pathway.
A10: Postnatal developmental weight applied to child utensils pathway | B10: =Inputs!$D$55*MIN(Inputs!$D$71,1)+B8*(MIN(MAX(Inputs!$D$71-1,0),4)/4) | C10: =Inputs!$F$55*MIN(Inputs!$F$71,1)+C8*(MIN(MAX(Inputs!$F$71-1,0),4)/4) | D10: Share of cognition-relevant window reached by the utensils pathway.
A11: Postnatal developmental weight applied to infant kohl pathway | B11: =Inputs!$D$55*MIN(Inputs!$D$70,1)+B8*(MIN(MAX(Inputs!$D$70-1,0),4)/4) | C11: =Inputs!$F$55*MIN(Inputs!$F$70,1)+C8*(MIN(MAX(Inputs!$F$70-1,0),4)/4) | D11: Share of cognition-relevant window reached by the infant kohl pathway.
A13: Kitchen package | D13: Default and local deterministic runs
A14: Kitchen: pot pathway success probability before residual unsafe-use penalty | B14: =Inputs!$D$27*Inputs!$D$32*Inputs!$D$38*Inputs!$D$39*Inputs!$D$40*Inputs!$D$41 | C14: =Inputs!$F$27*Inputs!$F$32*Inputs!$F$38*Inputs!$F$39*Inputs!$F$40*Inputs!$F$41 | D14: Probability.
A15: Kitchen: pot pathway success probability after residual unsafe-use penalty | B15: =B14*(1-Inputs!$D$42) | C15: =C14*(1-Inputs!$F$42) | D15: Probability.
A16: Kitchen: calcium pathway success probability | B16: =Inputs!$D$32*Inputs!$D$36*Inputs!$D$37 | C16: =Inputs!$F$32*Inputs!$F$36*Inputs!$F$37 | D16: Probability.
A17: Kitchen: child-utensils pathway success probability | B17: =Inputs!$D$30*Inputs!$D$33*Inputs!$D$36*Inputs!$D$37 | C17: =Inputs!$F$30*Inputs!$F$33*Inputs!$F$36*Inputs!$F$37 | D17: Probability.
A18: Kitchen: child BLL reduction from safe pot during active use | B18: =Inputs!$D$44*B15 | C18: =Inputs!$F$44*C15 | D18: ug/dL during intervention period.
A19: Kitchen: maternal BLL reduction from safe pot during active use | B19: =Inputs!$D$45*B15 | C19: =Inputs!$F$45*C15 | D19: ug/dL during intervention period.
A20: Kitchen: maternal BLL reduction from calcium during pregnancy | B20: =Inputs!$D$47*B16 | C20: =Inputs!$F$47*C16 | D20: ug/dL during intervention period.
A21: Kitchen: child BLL reduction from safe utensils during active use | B21: =Inputs!$D$46*B17 | C21: =Inputs!$F$46*C17 | D21: ug/dL during intervention period.
A22: Kitchen: fetal / prenatal child BLL reduction transmitted through the mother | B22: =Inputs!$D$53*(B19+B20) | C22: =Inputs!$F$53*(C19+C20) | D22: ug/dL equivalent.
A23: Kitchen: total child BLL reduction during intervention period | B23: =B18+B21+B22 | C23: =C18+C21+C22 | D23: ug/dL across active pathways before developmental weighting.
A24: Kitchen: developmentally weighted child BLL reduction used for cognition calculation | B24: =B22*Inputs!$D$54+B18*B9+B21*B10 | C24: =C22*Inputs!$F$54+C18*C9+C21*C10 | D24: ug/dL averaged over the relevant developmental window.
A25: Kitchen: child IQ gain | B25: =B24*Inputs!$D$51 | C25: =C24*Inputs!$F$51 | D25: IQ points.
A26: Kitchen: present value of lifetime earnings gain | B26: =B5*Inputs!$D$52*B25 | C26: =C5*Inputs!$F$52*C25 | D26: US$ per child.
A27: Kitchen: preeclampsia cases averted per mother | B27: =Inputs!$D$57-((Inputs!$D$57/(1-Inputs!$D$57))/POWER(Inputs!$D$58,(B19+B20)*Inputs!$D$61))/(1+((Inputs!$D$57/(1-Inputs!$D$57))/POWER(Inputs!$D$58,(B19+B20)*Inputs!$D$61))) | C27: =Inputs!$F$57-((Inputs!$F$57/(1-Inputs!$F$57))/POWER(Inputs!$F$58,(C19+C20)*Inputs!$F$61))/(1+((Inputs!$F$57/(1-Inputs!$F$57))/POWER(Inputs!$F$58,(C19+C20)*Inputs!$F$61))) | D27: Probability change. Used only in the maternal/neonatal-health-inclusive BCR.
A28: Kitchen: preterm births averted per mother | B28: =Inputs!$D$59-((Inputs!$D$59/(1-Inputs!$D$59))/POWER(Inputs!$D$60,(B19+B20)*Inputs!$D$62))/(1+((Inputs!$D$59/(1-Inputs!$D$59))/POWER(Inputs!$D$60,(B19+B20)*Inputs!$D$62))) | C28: =Inputs!$F$59-((Inputs!$F$59/(1-Inputs!$F$59))/POWER(Inputs!$F$60,(C19+C20)*Inputs!$F$62))/(1+((Inputs!$F$59/(1-Inputs!$F$59))/POWER(Inputs!$F$60,(C19+C20)*Inputs!$F$62))) | D28: Probability change. Used only in the maternal/neonatal-health-inclusive BCR.
A29: Kitchen: maternal and neonatal health benefit | B29: =B27*Inputs!$D$66*B7+B28*Inputs!$D$63*B7 | C29: =C27*Inputs!$F$66*C7+C28*Inputs!$F$63*C7 | D29: US$. Added only in the maternal/neonatal-health-inclusive BCRs.
A30: Kitchen: adult cardiovascular health benefit | B30: =((B19*Inputs!$D$68+B20*Inputs!$D$72)*Inputs!$D$64*B7*POWER(1+Inputs!$D$6,-MAX(0,Inputs!$D$73-Inputs!$D$11)))+(B18*Inputs!$D$64*Inputs!$D$68*B7*Inputs!$D$74*POWER(1+Inputs!$D$6,-MAX(0,Inputs!$D$73-Inputs!$D$12))*Inputs!$D$13) | C30: =((C19*Inputs!$F$68+C20*Inputs!$F$72)*Inputs!$F$64*C7*POWER(1+Inputs!$F$6,-MAX(0,Inputs!$F$73-Inputs!$F$11)))+(C18*Inputs!$F$64*Inputs!$F$68*C7*Inputs!$F$74*POWER(1+Inputs!$F$6,-MAX(0,Inputs!$F$73-Inputs!$F$12))*Inputs!$F$13) | D30: US$. Added only in the total BCR.
A31: Kitchen: total programme cost per mother-child pair | B31: =B6+Inputs!$D$20*Inputs!$D$32+(Inputs!$D$15+Inputs!$D$21)*(1+Inputs!$D$23)*Inputs!$D$32*Inputs!$D$38*Inputs!$D$39*Inputs!$D$40+Inputs!$D$20*Inputs!$D$32+Inputs!$D$22*(1+Inputs!$D$23)*Inputs!$D$32*Inputs!$D$36+Inputs!$D$17*(1+Inputs!$D$23)*Inputs!$D$32*Inputs!$D$36+Inputs!$D$20*Inputs!$D$33+Inputs!$D$22*(1+Inputs!$D$23)*Inputs!$D$33*Inputs!$D$36+Inputs!$D$16*(1+Inputs!$D$23)*Inputs!$D$33*Inputs!$D$36 | C31: =C6+Inputs!$F$20*Inputs!$F$32+(Inputs!$F$15+Inputs!$F$21)*(1+Inputs!$F$23)*Inputs!$F$32*Inputs!$F$38*Inputs!$F$39*Inputs!$F$40+Inputs!$F$20*Inputs!$F$32+Inputs!$F$22*(1+Inputs!$F$23)*Inputs!$F$32*Inputs!$F$36+Inputs!$F$17*(1+Inputs!$F$23)*Inputs!$F$32*Inputs!$F$36+Inputs!$F$20*Inputs!$F$33+Inputs!$F$22*(1+Inputs!$F$23)*Inputs!$F$33*Inputs!$F$36+Inputs!$F$16*(1+Inputs!$F$23)*Inputs!$F$33*Inputs!$F$36 | D31: US$. Includes fixed costs plus variable programme costs.
A32: Kitchen: benefit-cost ratio, cognition channel only | B32: =B26/B31 | C32: =C26/C31 | D32: Ratio.
A33: Kitchen: benefit-cost ratio, cognition plus maternal and neonatal health channels | B33: =(B26+B29)/B31 | C33: =(C26+C29)/C31 | D33: Ratio.
A34: Kitchen: benefit-cost ratio, cognition, maternal/neonatal, and cardiovascular health channels | B34: =(B26+B29+B30)/B31 | C34: =(C26+C29+C30)/C31 | D34: Ratio.
A36: Kohl package | D36: Default and local deterministic runs
A37: Kohl: maternal-kohl pathway success probability | B37: =Inputs!$D$28*Inputs!$D$32*Inputs!$D$36*Inputs!$D$37 | C37: =Inputs!$F$28*Inputs!$F$32*Inputs!$F$36*Inputs!$F$37 | D37: Probability.
A38: Kohl: infant-kohl pathway success probability | B38: =Inputs!$D$29*Inputs!$D$35*Inputs!$D$36*Inputs!$D$37 | C38: =Inputs!$F$29*Inputs!$F$35*Inputs!$F$36*Inputs!$F$37 | D38: Probability.
A39: Kohl: maternal BLL reduction from safe maternal kohl | B39: =Inputs!$D$48*B37 | C39: =Inputs!$F$48*C37 | D39: ug/dL during intervention period.
A40: Kohl: child BLL reduction from safe infant kohl | B40: =Inputs!$D$49*B38 | C40: =Inputs!$F$49*C38 | D40: ug/dL during intervention period.
A41: Kohl: fetal / prenatal child BLL reduction transmitted through the mother | B41: =Inputs!$D$53*B39 | C41: =Inputs!$F$53*C39 | D41: ug/dL equivalent.
A42: Kohl: total child BLL reduction during intervention period | B42: =B41+B40 | C42: =C41+C40 | D42: ug/dL across active pathways before developmental weighting.
...

Sheet Topline
A1: Output | B1: Units | C1: Workbook default: Kitchen | D1: Your local run: Kitchen | E1: Workbook default: Kohl | F1: Your local run: Kohl | G1: Delta Kitchen (local-default) | H1: Delta Kitchen (%) | I1: Delta Kohl (local-default) | J1: Delta Kohl (%)
A2: Direct outcomes
A3: Cost per mother-child pair (including fixed and variable programme costs) | B3: US$ | C3: =Results!$B$31 | D3: =Results!$C$31 | E3: =Results!$B$50 | F3: =Results!$C$50 | G3: =D3-C3 | H3: =IFERROR((D3-C3)/C3,0) | I3: =F3-E3 | J3: =IFERROR((F3-E3)/E3,0)
A4: Present value of lifetime earnings gain per child | B4: US$ | C4: =Results!$B$26 | D4: =Results!$C$26 | E4: =Results!$B$45 | F4: =Results!$C$45 | G4: =D4-C4 | H4: =IFERROR((D4-C4)/C4,0) | I4: =F4-E4 | J4: =IFERROR((F4-E4)/E4,0)
A5: Child BLL reduction during intervention period | B5: ug/dL | C5: =Results!$B$23 | D5: =Results!$C$23 | E5: =Results!$B$42 | F5: =Results!$C$42 | G5: =D5-C5 | H5: =IFERROR((D5-C5)/C5,0) | I5: =F5-E5 | J5: =IFERROR((F5-E5)/E5,0)
A6: Developmentally weighted child BLL reduction used for cognition calculation | B6: ug/dL | C6: =Results!$B$24 | D6: =Results!$C$24 | E6: =Results!$B$43 | F6: =Results!$C$43 | G6: =D6-C6 | H6: =IFERROR((D6-C6)/C6,0) | I6: =F6-E6 | J6: =IFERROR((F6-E6)/E6,0)
A7: Child IQ gain | B7: IQ points | C7: =Results!$B$25 | D7: =Results!$C$25 | E7: =Results!$B$44 | F7: =Results!$C$44 | G7: =D7-C7 | H7: =IFERROR((D7-C7)/C7,0) | I7: =F7-E7 | J7: =IFERROR((F7-E7)/E7,0)
A9: Benefit-cost ratios
A10: Benefit-cost ratio, cognition channel only | B10: Ratio | C10: =Results!$B$32 | D10: =Results!$C$32 | E10: =Results!$B$51 | F10: =Results!$C$51 | G10: =D10-C10 | H10: =IFERROR((D10-C10)/C10,0) | I10: =F10-E10 | J10: =IFERROR((F10-E10)/E10,0)
A11: Benefit-cost ratio, cognition plus maternal and neonatal health channels | B11: Ratio | C11: =Results!$B$33 | D11: =Results!$C$33 | E11: =Results!$B$52 | F11: =Results!$C$52 | G11: =D11-C11 | H11: =IFERROR((D11-C11)/C11,0) | I11: =F11-E11 | J11: =IFERROR((F11-E11)/E11,0)
A12: Benefit-cost ratio, cognition, maternal/neonatal health, and cardiovascular health channels | B12: Ratio | C12: =Results!$B$34 | D12: =Results!$C$34 | E12: =Results!$B$53 | F12: =Results!$C$53 | G12: =D12-C12 | H12: =IFERROR((D12-C12)/C12,0) | I12: =F12-E12 | J12: =IFERROR((F12-E12)/E12,0)
